<?xml version="1.0"?>
<robot name="myfirst" xmlns:xacro="http://www.ros.org/wiki/xacro">
	<xacro:include filename="$(find vajra_sim)/urdf/vajra.gazebo" />



	  <link name="robot_footprint"></link>


	  <joint name="robot_footprint_joint" type="fixed">
		<origin xyz="0 0 0" rpy="0 0 0" />
		<parent link="robot_footprint"/>
		<child link="body" />
	  </joint>

	<link name="body">
		<collision>
			<origin xyz="0 0 0" rpy="0 0 0" />
			<geometry>
				<mesh filename="package://vajra_sim/meshes/body/bot2.dae" />
			</geometry>
		</collision>
		<visual>
			<origin xyz="0 0 0" rpy="0 0 0" />
			<geometry>
				<mesh filename="package://vajra_sim/meshes/body/bot2.dae" />
			</geometry>
		</visual>
		<inertial>
			<origin xyz="0 0 0" rpy="0 0 0" />
			<mass value="15" />
			<inertia ixx="1.0" ixy="0.0" ixz="0.0" iyy="1.0" iyz="0.0" izz="1.0" />
		</inertial>
	</link>
	<link name="left_wheel">
		<collision>
			<origin xyz="0 0 0" rpy="0 0 0" />
			<geometry>
				<mesh filename="package://vajra_sim/meshes/wheels/tyre1.dae" />
				<box size="0.1 0.1 0.1"/>

			</geometry>
		</collision>
		<visual>
			<origin xyz="0 0 0" rpy="0 0 0" />
			<geometry>
				<mesh filename="package://vajra_sim/meshes/wheels/tyre1.dae" />
			</geometry>
		</visual>
		<inertial>
			<origin xyz="0 0 0" rpy="0 0 0" />
			<mass value="5" />
			<inertia ixx="1.0" ixy="0.0" ixz="0.0" iyy="1.0" iyz="0.0" izz="1.0" />
		</inertial>
	</link>

	<joint name="left_wheel_body" type="continuous">
		<origin xyz="0 0.323 0" rpy="0 0 0" />
		<axis xyz="0 1 0" rpy="0 0 0" />
		<parent link="body" />
		<child link="left_wheel" />
		<limit effort="10000" velocity="1000" />
    <dynamics damping="1.0" friction="1.0" />
	</joint>

	<link name="right_wheel">
		<collision>
			<origin xyz="0 0 0" rpy="0 0 0" />
			<geometry>
				<mesh filename="package://vajra_sim/meshes/wheels/tyre1.dae" />
			</geometry>
		</collision>
		<visual>
			<origin xyz="0 0 0" rpy="0 0 0" />
			<geometry>
				<mesh filename="package://vajra_sim/meshes/wheels/tyre1.dae" />
			</geometry>
		</visual>
		<inertial>
			<origin xyz="0 0 0" rpy="0 0 0" />
			<mass value="5" />
			<inertia ixx="1.0" ixy="0.0" ixz="0.0" iyy="1.0" iyz="0.0" izz="1.0" />
		</inertial>
	</link>


	<joint name="right_wheel_body" type="continuous">
		<origin xyz="0 -0.323 0" rpy="0 0 0" />
		<axis xyz="0 1 0" rpy="0 0 0" />
		<parent link="body" />
		<child link="right_wheel" />
		<limit effort="10000" velocity="1000" />
    <dynamics damping="1.0" friction="1.0" />
	</joint>
	
	<link name="castor">
		<collision>
			<origin xyz="0 0 0" rpy="0 0 0" />
			<geometry>
				<mesh filename="package://vajra_sim/meshes/wheels/castors1.dae" />
			</geometry>
		</collision>
		<visual>
			<origin xyz="0 0 0" rpy="0 0 0" />
			<geometry>
				<mesh filename="package://vajra_sim/meshes/wheels/castors1.dae" />
			</geometry>
		</visual>
		<inertial>
			<origin xyz="0 0 0" rpy="0 0 0" />
			<mass value="5" />
			<inertia ixx="1.0" ixy="0.0" ixz="0.0" iyy="1.0" iyz="0.0" izz="1.0" />
		</inertial>
	</link>
	<joint name="castor_to_body" type="fixed">
		<origin xyz="0.48 0 0.02" rpy="0 0 0" />
		<axis xyz="0 1 0" rpy="0 0 0" />
		<parent link="body" />
		<child link="castor" />
	</joint>


  
  <!-- Camera -->
  <link name="camera_link">
    <collision>
      <origin xyz="0 0 0" rpy="0 0 0"/>
      <geometry>
        <box size="0.1 0.1 0.1"/>
    
      </geometry>
    </collision>

    <visual>
      <origin xyz="0 0 0" rpy="0 0 0"/>
      <geometry>
    <box size="0.1 0.1 0.1"/>
      </geometry>
      <material name="red"/>
    </visual>

    <inertial>
      <mass value="1e-5" />
      <origin xyz="0 0 0" rpy="0 0 0"/>
      <inertia ixx="1e-6" ixy="0" ixz="0" iyy="1e-6" iyz="0" izz="1e-6" />
    </inertial>
  </link>


  <joint name="camera_joint" type="fixed">
    <axis xyz="0 1 0" />
    <origin xyz="0.73 0 1.18" rpy="0 0.45 0"/>
    <parent link="body"/>
    <child link="camera_link"/>
  </joint>


 
</robot>
